Workbook

Sheet README
A1: Annex: Manual vs automatic interview duration (Household and Girls surveys)
A2: Only three fields are used: starttime1, Endtime1 (manual) and duration (automatic). Source: SurveyCTO exports of 28 October 2026 (Household_Survey.csv, Girls_Survey.csv). Every row can be matched to the export by KEY.
A4: Definitions
A5: Manual duration (min) = Endtime1 - starttime1 (times typed by the enumerator).
A6: Automatic duration (min) = duration / 60 (SurveyCTO duration(), active on-screen seconds).
A7: Gap (min) = manual duration used - automatic duration.
A9: Rules applied to manual duration (column 'action' in sheet Forms)
A10: 1. Used as recorded: 0 <= manual duration <= 180 min.
A11: 2. Corrected: date: Endtime1 date differs from starttime1 date; Endtime1 date set to the starttime1 date; result within 0-180 min.
A12: 3. Corrected: AM/PM: start or end shifted by 12 hours; accepted only if the result is within 0-180 min, and the start date is unchanged.
A13: 4. Excluded: none of the above gives a valid duration. Excluded forms are removed from BOTH the manual and automatic means.

Sheet Summary
A1: Survey | B1: Enumerator | C1: Reported: manual mean | D1: Reported: auto mean | E1: Forms used | F1: Manual mean (min) | G1: Auto mean (min) | H1: Gap (min)
A2: Household | B2: Asma Bibi | C2: 58 | D2: 31 | E2: =COUNTIFS(Forms!$A$2:$A$2036,$A2,Forms!$D$2:$D$2036,$B2,Forms!$J$2:$J$2036,"<>Excluded") -> 140 | F2: =ROUND(AVERAGEIFS(Forms!$K$2:$K$2036,Forms!$A$2:$A$2036,$A2,Forms!$D$2:$D$2036,$B2,Forms!$J$2:$J$2036,"<>Excluded"),1) -> 43.4 | G2: =ROUND(AVERAGEIFS(Forms!$L$2:$L$2036,Forms!$A$2:$A$2036,$A2,Forms!$D$2:$D$2036,$B2,Forms!$J$2:$J$2036,"<>Excluded"),1) -> 28.3 | H2: =ROUND(AVERAGEIFS(Forms!$K$2:$K$2036,Forms!$A$2:$A$2036,$A2,Forms!$D$2:$D$2036,$B2,Forms!$J$2:$J$2036,"<>Excluded")-AVERAGEIFS(Forms!$L$2:$L$2036,Forms!$A$2:$A$2036,$A2,Forms!$D$2:$D$2036,$B2,Forms!$J$2:$J$2036,"<>Excluded"),1) -> 15.1
A3: Household | B3: Aisha Aman | C3: 55 | D3: 30 | E3: =COUNTIFS(Forms!$A$2:$A$2036,$A3,Forms!$D$2:$D$2036,$B3,Forms!$J$2:$J$2036,"<>Excluded") -> 77 | F3: =ROUND(AVERAGEIFS(Forms!$K$2:$K$2036,Forms!$A$2:$A$2036,$A3,Forms!$D$2:$D$2036,$B3,Forms!$J$2:$J$2036,"<>Excluded"),1) -> 46.2 | G3: =ROUND(AVERAGEIFS(Forms!$L$2:$L$2036,Forms!$A$2:$A$2036,$A3,Forms!$D$2:$D$2036,$B3,Forms!$J$2:$J$2036,"<>Excluded"),1) -> 33.6 | H3: =ROUND(AVERAGEIFS(Forms!$K$2:$K$2036,Forms!$A$2:$A$2036,$A3,Forms!$D$2:$D$2036,$B3,Forms!$J$2:$J$2036,"<>Excluded")-AVERAGEIFS(Forms!$L$2:$L$2036,Forms!$A$2:$A$2036,$A3,Forms!$D$2:$D$2036,$B3,Forms!$J$2:$J$2036,"<>Excluded"),1) -> 12.7
A4: Household | B4: Mahnoor | C4: 67 | D4: 45 | E4: =COUNTIFS(Forms!$A$2:$A$2036,$A4,Forms!$D$2:$D$2036,$B4,Forms!$J$2:$J$2036,"<>Excluded") -> 115 | F4: =ROUND(AVERAGEIFS(Forms!$K$2:$K$2036,Forms!$A$2:$A$2036,$A4,Forms!$D$2:$D$2036,$B4,Forms!$J$2:$J$2036,"<>Excluded"),1) -> 45.2 | G4: =ROUND(AVERAGEIFS(Forms!$L$2:$L$2036,Forms!$A$2:$A$2036,$A4,Forms!$D$2:$D$2036,$B4,Forms!$J$2:$J$2036,"<>Excluded"),1) -> 35.4 | H4: =ROUND(AVERAGEIFS(Forms!$K$2:$K$2036,Forms!$A$2:$A$2036,$A4,Forms!$D$2:$D$2036,$B4,Forms!$J$2:$J$2036,"<>Excluded")-AVERAGEIFS(Forms!$L$2:$L$2036,Forms!$A$2:$A$2036,$A4,Forms!$D$2:$D$2036,$B4,Forms!$J$2:$J$2036,"<>Excluded"),1) -> 9.7
A5: Household | B5: Naureen Khan | E5: =COUNTIFS(Forms!$A$2:$A$2036,$A5,Forms!$D$2:$D$2036,$B5,Forms!$J$2:$J$2036,"<>Excluded") -> 102 | F5: =ROUND(AVERAGEIFS(Forms!$K$2:$K$2036,Forms!$A$2:$A$2036,$A5,Forms!$D$2:$D$2036,$B5,Forms!$J$2:$J$2036,"<>Excluded"),1) -> 39.3 | G5: =ROUND(AVERAGEIFS(Forms!$L$2:$L$2036,Forms!$A$2:$A$2036,$A5,Forms!$D$2:$D$2036,$B5,Forms!$J$2:$J$2036,"<>Excluded"),1) -> 24.8 | H5: =ROUND(AVERAGEIFS(Forms!$K$2:$K$2036,Forms!$A$2:$A$2036,$A5,Forms!$D$2:$D$2036,$B5,Forms!$J$2:$J$2036,"<>Excluded")-AVERAGEIFS(Forms!$L$2:$L$2036,Forms!$A$2:$A$2036,$A5,Forms!$D$2:$D$2036,$B5,Forms!$J$2:$J$2036,"<>Excluded"),1) -> 14.5
A6: Girls | B6: Aisha Aman | C6: 35 | D6: 18 | E6: =COUNTIFS(Forms!$A$2:$A$2036,$A6,Forms!$D$2:$D$2036,$B6,Forms!$J$2:$J$2036,"<>Excluded") -> 42 | F6: =ROUND(AVERAGEIFS(Forms!$K$2:$K$2036,Forms!$A$2:$A$2036,$A6,Forms!$D$2:$D$2036,$B6,Forms!$J$2:$J$2036,"<>Excluded"),1) -> 24.4 | G6: =ROUND(AVERAGEIFS(Forms!$L$2:$L$2036,Forms!$A$2:$A$2036,$A6,Forms!$D$2:$D$2036,$B6,Forms!$J$2:$J$2036,"<>Excluded"),1) -> 20.7 | H6: =ROUND(AVERAGEIFS(Forms!$K$2:$K$2036,Forms!$A$2:$A$2036,$A6,Forms!$D$2:$D$2036,$B6,Forms!$J$2:$J$2036,"<>Excluded")-AVERAGEIFS(Forms!$L$2:$L$2036,Forms!$A$2:$A$2036,$A6,Forms!$D$2:$D$2036,$B6,Forms!$J$2:$J$2036,"<>Excluded"),1) -> 3.7
A7: Girls | B7: Shazia Bibi | C7: 35 | D7: 20 | E7: =COUNTIFS(Forms!$A$2:$A$2036,$A7,Forms!$D$2:$D$2036,$B7,Forms!$J$2:$J$2036,"<>Excluded") -> 75 | F7: =ROUND(AVERAGEIFS(Forms!$K$2:$K$2036,Forms!$A$2:$A$2036,$A7,Forms!$D$2:$D$2036,$B7,Forms!$J$2:$J$2036,"<>Excluded"),1) -> 31.3 | G7: =ROUND(AVERAGEIFS(Forms!$L$2:$L$2036,Forms!$A$2:$A$2036,$A7,Forms!$D$2:$D$2036,$B7,Forms!$J$2:$J$2036,"<>Excluded"),1) -> 26.1 | H7: =ROUND(AVERAGEIFS(Forms!$K$2:$K$2036,Forms!$A$2:$A$2036,$A7,Forms!$D$2:$D$2036,$B7,Forms!$J$2:$J$2036,"<>Excluded")-AVERAGEIFS(Forms!$L$2:$L$2036,Forms!$A$2:$A$2036,$A7,Forms!$D$2:$D$2036,$B7,Forms!$J$2:$J$2036,"<>Excluded"),1) -> 5.2
A8: Girls | B8: Shafaq Zahra | C8: 33 | D8: 11 | E8: =COUNTIFS(Forms!$A$2:$A$2036,$A8,Forms!$D$2:$D$2036,$B8,Forms!$J$2:$J$2036,"<>Excluded") -> 74 | F8: =ROUND(AVERAGEIFS(Forms!$K$2:$K$2036,Forms!$A$2:$A$2036,$A8,Forms!$D$2:$D$2036,$B8,Forms!$J$2:$J$2036,"<>Excluded"),1) -> 26.8 | G8: =ROUND(AVERAGEIFS(Forms!$L$2:$L$2036,Forms!$A$2:$A$2036,$A8,Forms!$D$2:$D$2036,$B8,Forms!$J$2:$J$2036,"<>Excluded"),1) -> 23.9 | H8: =ROUND(AVERAGEIFS(Forms!$K$2:$K$2036,Forms!$A$2:$A$2036,$A8,Forms!$D$2:$D$2036,$B8,Forms!$J$2:$J$2036,"<>Excluded")-AVERAGEIFS(Forms!$L$2:$L$2036,Forms!$A$2:$A$2036,$A8,Forms!$D$2:$D$2036,$B8,Forms!$J$2:$J$2036,"<>Excluded"),1) -> 2.9
A9: Girls | B9: Naureen Khan | E9: =COUNTIFS(Forms!$A$2:$A$2036,$A9,Forms!$D$2:$D$2036,$B9,Forms!$J$2:$J$2036,"<>Excluded") -> 56 | F9: =ROUND(AVERAGEIFS(Forms!$K$2:$K$2036,Forms!$A$2:$A$2036,$A9,Forms!$D$2:$D$2036,$B9,Forms!$J$2:$J$2036,"<>Excluded"),1) -> 45.8 | G9: =ROUND(AVERAGEIFS(Forms!$L$2:$L$2036,Forms!$A$2:$A$2036,$A9,Forms!$D$2:$D$2036,$B9,Forms!$J$2:$J$2036,"<>Excluded"),1) -> 25.5 | H9: =ROUND(AVERAGEIFS(Forms!$K$2:$K$2036,Forms!$A$2:$A$2036,$A9,Forms!$D$2:$D$2036,$B9,Forms!$J$2:$J$2036,"<>Excluded")-AVERAGEIFS(Forms!$L$2:$L$2036,Forms!$A$2:$A$2036,$A9,Forms!$D$2:$D$2036,$B9,Forms!$J$2:$J$2036,"<>Excluded"),1) -> 20.3

Sheet Forms
A1: survey | B1: KEY | C1: enumerator_name (as in export) | D1: enumerator (standardised) | E1: girl | F1: starttime1 | G1: Endtime1 | H1: duration (sec) | I1: manual_raw_min | J1: action | K1: manual_used_min | L1: auto_min | M1: gap_min (manual-auto)
A2: Girls | B2: uuid:02113009-4ca5-4192-b505-37f7dd6fe526 | C2: aisha.aman | D2: Aisha Aman | E2: 1-14303-23-9d3372a3-13 | F2: Sep 29, 2026 12:00:00 PM | G2: Sep 29, 2026 12:13:00 PM | H2: 860 | I2: 13 | J2: Used as recorded | K2: 13 | L2: 14.33 | M2: -1.33
A3: Girls | B3: uuid:05ab83f2-0ed6-44d5-bcdf-243cc94db7fd | C3: aisha.aman | D3: Aisha Aman | E3: 1-38337-23-3f44a534-13 | F3: Oct 20, 2026 11:39:00 AM | G3: Oct 20, 2026 12:15:00 PM | H3: 1305 | I3: 36 | J3: Used as recorded | K3: 36 | L3: 21.75 | M3: 14.25
A4: Girls | B4: uuid:07980b59-45a2-4f41-9669-44390144f460 | C4: aisha.aman | D4: Aisha Aman | E4: 1-14271-23-8a01efd3-2 | F4: Oct 28, 2026 3:00:00 PM | G4: Oct 28, 2026 3:38:00 PM | H4: 1064 | I4: 38 | J4: Used as recorded | K4: 38 | L4: 17.73 | M4: 20.27
A5: Girls | B5: uuid:0d9f446e-5328-46ac-85b3-66ed6631dde3 | C5: aisha.aman | D5: Aisha Aman | E5: 83 | F5: Sep 29, 2026 2:56:00 PM | G5: Sep 29, 2026 3:33:00 PM | H5: 2493 | I5: 37 | J5: Used as recorded | K5: 37 | L5: 41.55 | M5: -4.55
A6: Girls | B6: uuid:0dbb44c6-5a5b-49ff-bf61-77d02ecf1700 | C6: aisha.aman | D6: Aisha Aman | E6: 1-14271-23-628fdb65-9 | F6: Oct 28, 2026 1:30:00 PM | G6: Oct 28, 2026 2:02:00 PM | H6: 1033 | I6: 32 | J6: Used as recorded | K6: 32 | L6: 17.22 | M6: 14.78
A7: Girls | B7: uuid:0e9bf726-3ec7-4d70-999c-5ba511c3b8ec | C7: aisha.aman | D7: Aisha Aman | E7: 1-38337-24-a8a19cad-11 | F7: Oct 20, 2026 3:32:00 PM | G7: Oct 20, 2026 4:00:00 PM | H7: 1356 | I7: 28 | J7: Used as recorded | K7: 28 | L7: 22.6 | M7: 5.4
A8: Girls | B8: uuid:20e2cd78-3cc3-49a4-9cc4-2f5c5c45175e | C8: aisha.aman | D8: Aisha Aman | E8: 1-28943-23-398ead58-4 | F8: Oct 21, 2026 4:00:00 PM | G8: Oct 21, 2026 4:34:00 PM | H8: 1229 | I8: 34 | J8: Used as recorded | K8: 34 | L8: 20.48 | M8: 13.52
A9: Girls | B9: uuid:2301463d-881d-4ebd-9bfc-9702af61d37b | C9: aisha.aman | D9: Aisha Aman | E9: 1-28928-24-50144bde-1 | F9: Oct 3, 2026 10:50:00 AM | G9: Oct 3, 2026 11:37:00 AM | H9: 1036 | I9: 47 | J9: Used as recorded | K9: 47 | L9: 17.27 | M9: 29.73
A10: Girls | B10: uuid:2967201d-d1a2-40a6-a1d9-1a6bc523146c | C10: aisha.aman | D10: Aisha Aman | E10: 1-14188-24-a011de7b-8 | F10: Oct 1, 2026 3:24:00 PM | G10: Oct 1, 2026 3:41:00 PM | H10: 1073 | I10: 17 | J10: Used as recorded | K10: 17 | L10: 17.88 | M10: -0.88
A11: Girls | B11: uuid:2a3a7156-e94b-4e30-afe1-74c553e7b7fe | C11: aisha.aman | D11: Aisha Aman | E11: 1-14230-23-85758577-3 | F11: Oct 23, 2026 2:41:00 AM | G11: Oct 23, 2026 3:10:00 AM | H11: 1136 | I11: 29 | J11: Used as recorded | K11: 29 | L11: 18.93 | M11: 10.07
A12: Girls | B12: uuid:2f75866d-ccec-4018-b7c8-699c1be86bd7 | C12: aisha.aman | D12: Aisha Aman | E12: 1-14285-24-56e3ee27-2 | F12: Oct 7, 2026 2:20:00 PM | G12: Oct 7, 2026 2:38:00 PM | H12: 1133 | I12: 18 | J12: Used as recorded | K12: 18 | L12: 18.88 | M12: -0.88
A13: Girls | B13: uuid:3279aade-d526-4b22-91de-776beeacd1ed | C13: aisha.aman | D13: Aisha Aman | E13: 1489 | F13: Oct 22, 2026 11:35:00 AM | G13: Oct 22, 2026 12:00:00 PM | H13: 766 | I13: 25 | J13: Used as recorded | K13: 25 | L13: 12.77 | M13: 12.23
... A16: Girls | B16: uuid:3ac67c2a-40ca-4b6b-b213-f7b064619633 | C16: aisha.aman | D16: Aisha Aman | E16: 1-14306-24-9360e7ba-6 | F16: Oct 9, 2026 1:47:00 PM | G16: Oct 9, 2026 2:17:00 PM | H16: 1829 | I16: 30 | J16: Used as recorded | K16: 30 | L16: 30.48 | M16: -0.48
A17: Girls | B17: uuid:3b939334-24b0-4211-9f6f-250c8da973ab | C17: aisha.aman | D17: Aisha Aman | E17: 1-14230-23-b71fba80-5 | F17: Oct 22, 2026 11:51:00 PM | G17: Oct 22, 2026 12:20:00 AM | H17: 1088 | I17: -1411 | J17: Excluded | L17: 18.13
A18: Girls | B18: uuid:416350d1-26a2-424d-88b9-b76cee88e2d5 | C18: aisha.aman | D18: Aisha Aman | E18: 1-14262-23-48b6238e-1 | F18: Oct 13, 2026 4:25:00 PM | G18: Oct 13, 2026 4:26:00 PM | H18: 291 | I18: 1 | J18: Used as recorded | K18: 1 | L18: 4.85 | M18: -3.85
A19: Girls | B19: uuid:41f99072-e37e-4fa0-ac2d-99a42198434b | C19: aisha.aman | D19: Aisha Aman | E19: 1-14209-24-5cfb066f-17 | F19: Oct 10, 2026 3:13:00 PM | G19: Oct 10, 2026 3:36:00 PM | H19: 1417 | I19: 23 | J19: Used as recorded | K19: 23 | L19: 23.62 | M19: -0.62
A20: Girls | B20: uuid:6531fd38-ac00-4caf-b3a8-77e8cdf544f9 | C20: aisha.aman | D20: Aisha Aman | E20: 1231 | F20: Oct 10, 2026 10:05:00 AM | G20: Oct 10, 2026 10:40:00 AM | H20: 2130 | I20: 35 | J20: Used as recorded | K20: 35 | L20: 35.5 | M20: -0.5
A21: Girls | B21: uuid:6ae1b2c9-e360-40a0-99a7-c33f0de675c4 | C21: aisha.aman | D21: Aisha Aman | E21: 147 | F21: Sep 30, 2026 1:50:00 PM | G21: Sep 30, 2026 2:10:00 PM | H21: 1219 | I21: 20 | J21: Used as recorded | K21: 20 | L21: 20.32 | M21: -0.32
A22: Girls | B22: uuid:7386cdf8-5d38-4203-a84d-3097e7458ab9 | C22: aisha.aman | D22: Aisha Aman | E22: 265 | F22: Oct 3, 2026 12:36:00 PM | G22: Oct 3, 2026 12:38:00 PM | H22: 196 | I22: 2 | J22: Used as recorded | K22: 2 | L22: 3.27 | M22: -1.27
A23: Girls | B23: uuid:80a477ec-2429-4455-a5d6-e1e94e2a7b6c | C23: aisha.aman | D23: Aisha Aman | E23: 1-28928-23-784928c7-2 | F23: Oct 3, 2026 12:22:00 PM | G23: Oct 3, 2026 12:29:00 PM | H23: 337 | I23: 7 | J23: Used as recorded | K23: 7 | L23: 5.62 | M23: 1.38
A24: Girls | B24: uuid:8c2fbd8b-2e74-477b-95f1-e630c929476f | C24: aisha.aman | D24: Aisha Aman | E24: 1-14262-24-14a9d9b0-4 | F24: Oct 13, 2026 2:14:00 PM | G24: Oct 13, 2026 2:14:00 PM | H24: 203 | I24: 0 | J24: Used as recorded | K24: 0 | L24: 3.38 | M24: -3.38
A25: Girls | B25: uuid:8f915672-33a2-4a91-a656-4827d1113f93 | C25: aisha.aman | D25: Aisha Aman | E25: 1-28943-24-b74fb0fe-11 | F25: Oct 21, 2026 12:05:00 PM | G25: Oct 21, 2026 12:30:00 PM | H25: 1129 | I25: 25 | J25: Used as recorded | K25: 25 | L25: 18.82 | M25: 6.18
A26: Girls | B26: uuid:905bac1a-f884-453f-adb8-1463c8a0789a | C26: aisha.aman | D26: Aisha Aman | E26: 1-14235-24-6f85abe4-8 | F26: Oct 12, 2026 4:12:00 PM | G26: Oct 12, 2026 4:37:00 PM | H26: 1493 | I26: 25 | J26: Used as recorded | K26: 25 | L26: 24.88 | M26: 0.12
A27: Girls | B27: uuid:960e3a63-197a-4dee-8642-47bb16507f85 | C27: aisha.aman | D27: Aisha Aman | E27: 1-14188-24-a294f259-6 | F27: Oct 1, 2026 12:41:00 PM | G27: Oct 1, 2026 1:07:00 PM | H27: 1591 | I27: 26 | J27: Used as recorded | K27: 26 | L27: 26.52 | M27: -0.52
A28: Girls | B28: uuid:966ff9af-1209-48db-822a-45ad9834c77a | C28: aisha.aman | D28: Aisha Aman | E28: 1-29114-23-a1316620-3 | F28: Oct 8, 2026 4:53:00 PM | G28: Oct 8, 2026 5:22:00 PM | H28: 1714 | I28: 29 | J28: Used as recorded | K28: 29 | L28: 28.57 | M28: 0.43
A29: Girls | B29: uuid:96d72483-6bef-4de7-93d5-26c19966b50a | C29: aisha.aman | D29: Aisha Aman | E29: 1-14262-24-20abea95-8 | F29: Oct 13, 2026 12:06:00 PM | G29: Oct 13, 2026 12:35:00 PM | H29: 1167 | I29: 29 | J29: Used as recorded | K29: 29 | L29: 19.45 | M29: 9.55
... A43: Girls | B43: uuid:e696f9b4-3f06-476f-b0a8-da14f868acd9 | C43: aisha.aman | D43: Aisha Aman | E43: 1-14284-24-87a8a72f-2 | F43: Oct 8, 2026 1:42:00 PM | G43: Oct 8, 2026 2:18:00 PM | H43: 2255 | I43: 36 | J43: Used as recorded | K43: 36 | L43: 37.58 | M43: -1.58
A44: Girls | B44: uuid:ea44d86a-a906-406d-9a48-7d81817a213f | C44: aisha.aman | D44: Aisha Aman | E44: 1-28943-24-aa481047-8 | F44: Oct 21, 2026 3:05:00 PM | G44: Oct 21, 2026 2:32:00 PM | H44: 1065 | I44: -33 | J44: Excluded | L44: 17.75
A45: Girls | B45: uuid:fd921e5c-0873-4a4e-b547-eaec61e0f5aa | C45: aisha.aman | D45: Aisha Aman | E45: 1-14306-23-daf900d2-5 | F45: Oct 9, 2026 10:57:00 AM | G45: Oct 9, 2026 11:26:00 AM | H45: 1826 | I45: 29 | J45: Used as recorded | K45: 29 | L45: 30.43 | M45: -1.43
A46: Girls | B46: uuid:07f6df74-f8fc-49ad-94c5-de93ddd273cc | C46: Asma Bibi | D46: Asma Bibi | E46: 1-14360-23-7e664539-2 | F46: Oct 2, 2026 3:00:00 PM | G46: Oct 2, 2026 3:14:00 PM | H46: 666 | I46: 14 | J46: Used as recorded | K46: 14 | L46: 11.1 | M46: 2.9
A47: Girls | B47: uuid:10915d21-2bc9-4468-a296-a460cfdce5fd | C47: Asma Bibi | D47: Asma Bibi | E47: 1-14391-23-9e8f6895-15 | F47: Sep 17, 2026 11:23:00 PM | G47: Sep 17, 2026 11:50:00 PM | H47: 1223 | I47: 27 | J47: Used as recorded | K47: 27 | L47: 20.38 | M47: 6.62
A48: Girls | B48: uuid:11a9185a-6323-49fc-97f5-415451e66814 | C48: Asma Bibi | D48: Asma Bibi | E48: 1-14155-23-7c9beeea-3 | F48: Sep 20, 2026 11:27:00 PM | G48: Sep 20, 2026 11:43:00 PM | H48: 1032 | I48: 16 | J48: Used as recorded | K48: 16 | L48: 17.2 | M48: -1.2
A49: Girls | B49: uuid:165198c2-5d0a-4245-a066-cef45f95ada5 | C49: Asma Bibi | D49: Asma Bibi | E49: 1-29159-23-fc9a984e-2 | F49: Sep 16, 2026 10:41:00 AM | G49: Sep 16, 2026 11:01:00 AM | H49: 1110 | I49: 20 | J49: Used as recorded | K49: 20 | L49: 18.5 | M49: 1.5
A50: Girls | B50: uuid:1770e2da-e1e4-419d-9d7d-a6a46cffa438 | C50: Asma Bibi | D50: Asma Bibi | E50: 1-14391-24-11c72ce2-10 | F50: Sep 20, 2026 1:46:00 AM | G50: Sep 20, 2026 2:05:00 AM | H50: 1128 | I50: 19 | J50: Used as recorded | K50: 19 | L50: 18.8 | M50: 0.2
A51: Girls | B51: uuid:219c10f0-714e-47e5-aaf4-005da96e2299 | C51: Asma Bibi | D51: Asma Bibi | E51: 1-14338-24-4366708d-3 | F51: Oct 27, 2026 11:19:00 AM | G51: Oct 27, 2026 11:49:00 AM | H51: 1717 | I51: 30 | J51: Used as recorded | K51: 30 | L51: 28.62 | M51: 1.38
A52: Girls | B52: uuid:240ceb73-220d-4fde-a89b-755259207a61 | C52: Asma Bibi | D52: Asma Bibi | E52: 1-14262-23-ea0b6e63-8 | F52: Oct 13, 2026 3:12:00 PM | G52: Oct 13, 2026 3:21:00 PM | H52: 405 | I52: 9 | J52: Used as recorded | K52: 9 | L52: 6.75 | M52: 2.25
A53: Girls | B53: uuid:250efecc-d7a9-452a-a0c1-c35adf4dc427 | C53: Asma Bibi | D53: Asma Bibi | E53: 1236 | F53: Oct 22, 2026 11:38:00 AM | G53: Oct 22, 2026 12:06:00 PM | H53: 1029 | I53: 28 | J53: Used as recorded | K53: 28 | L53: 17.15 | M53: 10.85
A54: Girls | B54: uuid:2a43b35f-1717-4f09-88aa-8ad79508e5e5 | C54: Asma Bibi | D54: Asma Bibi | E54: 1-14271-23-fceeae2d-10 | F54: Oct 28, 2026 1:10:00 PM | G54: Oct 28, 2026 1:45:00 PM | H54: 1048 | I54: 35 | J54: Used as recorded | K54: 35 | L54: 17.47 | M54: 17.53
A55: Girls | B55: uuid:2c70fae0-e044-4302-aa40-1eed3a4ea3da | C55: Asma Bibi | D55: Asma Bibi | E55: 1-14256-24-380c263e-8 | F55: Sep 28, 2026 5:09:00 PM | G55: Sep 28, 2026 5:22:00 PM | H55: 809 | I55: 13 | J55: Used as recorded | K55: 13 | L55: 13.48 | M55: -0.48
...

Sheet Corrections
A1: survey | B1: KEY | C1: enumerator_name (as in export) | D1: enumerator (standardised) | E1: girl | F1: starttime1 | G1: Endtime1 | H1: duration (sec) | I1: manual_raw_min | J1: action | K1: manual_used_min | L1: auto_min | M1: gap_min (manual-auto)
A2: Girls | B2: uuid:3b939334-24b0-4211-9f6f-250c8da973ab | C2: aisha.aman | D2: Aisha Aman | E2: 1-14230-23-b71fba80-5 | F2: Oct 22, 2026 11:51:00 PM | G2: Oct 22, 2026 12:20:00 AM | H2: 1088 | I2: -1411 | J2: Excluded | L2: 18.13
A3: Girls | B3: uuid:ea44d86a-a906-406d-9a48-7d81817a213f | C3: aisha.aman | D3: Aisha Aman | E3: 1-28943-24-aa481047-8 | F3: Oct 21, 2026 3:05:00 PM | G3: Oct 21, 2026 2:32:00 PM | H3: 1065 | I3: -33 | J3: Excluded | L3: 17.75
A4: Girls | B4: uuid:a4ea8bdc-498e-4a83-968b-85a8b6e274e0 | C4: Asma Bibi | D4: Asma Bibi | E4: 1-39399-24-1d926d8d-20 | F4: Sep 9, 2026 8:51:00 AM | G4: Sep 9, 2026 1:19:00 PM | H4: 3192 | I4: 268 | J4: Excluded | L4: 53.2
A5: Girls | B5: uuid:f95728dd-f099-4ef7-b7b4-53d24a4c46cf | C5: Irum Ikram | D5: Irum Ikram | E5: 1381 | F5: Sep 9, 2026 2:00:00 AM | G5: Sep 9, 2026 3:20:00 PM | H5: 3638 | I5: 800 | J5: Corrected: AM/PM | K5: 80 | L5: 60.63 | M5: 19.37
A6: Girls | B6: uuid:1e4f3faf-6e26-4f1f-9b3b-3b950ffe0cfc | C6: Javairia | D6: Javairia | E6: 1776 | F6: Sep 11, 2026 12:47:00 AM | G6: Sep 11, 2026 4:34:00 PM | H6: 2058 | I6: 947 | J6: Excluded | L6: 34.3
A7: Girls | B7: uuid:84759abf-6623-49e2-ab68-59becd2abbba | C7: Javairia | D7: Javairia | E7: 1777 | F7: Sep 10, 2026 11:22:00 PM | G7: Sep 11, 2026 4:47:00 AM | H7: 2225 | I7: 325 | J7: Excluded | L7: 37.08
A8: Girls | B8: uuid:c61c63f9-814f-4475-b5b5-353ee102b607 | C8: Javairia | D8: Javairia | E8: 1-14360-23-e87d0ba6-4 | F8: Sep 2, 2026 2:41:00 PM | G8: Oct 2, 2026 3:07:00 PM | H8: 1600 | I8: 43226 | J8: Corrected: date | K8: 26 | L8: 26.67 | M8: -0.67
A9: Girls | B9: uuid:7fad4f04-ac02-47d1-b25b-ecab27034177 | C9: Naureen Khan | D9: Naureen Khan | E9: 1-14285-24-8b710a45-7 | F9: Oct 24, 2026 10:55:00 AM | G9: Oct 8, 2026 12:25:00 PM | H9: 1796 | I9: -22950 | J9: Corrected: date | K9: 90 | L9: 29.93 | M9: 60.07
A10: Girls | B10: uuid:199ea468-989d-4f8f-85c5-bf5800e6c4fa | C10: Shafaq Zahra | D10: Shafaq Zahra | E10: 1-37622-24-b055945b-2 | F10: Oct 26, 2026 12:25:00 AM | G10: Oct 26, 2026 1:06:00 PM | H10: 1382 | I10: 761 | J10: Corrected: AM/PM | K10: 41 | L10: 23.03 | M10: 17.97
A11: Girls | B11: uuid:a1576632-c7ad-42b7-a8e3-67c2535a9de2 | C11: Shafaq Zahra | D11: Shafaq Zahra | E11: 1-29114-23-a1316620-3 | F11: Sep 17, 2026 12:14:00 PM | G11: Sep 17, 2026 12:09:00 PM | H11: 1985 | I11: -5 | J11: Excluded | L11: 33.08
A12: Household | B12: uuid:03e8bbdd-167a-41c0-bce0-362688e0745b | C12: aisha.aman | D12: Aisha Aman | E12: 1-28943-24-b74fb0fe-11 | F12: Oct 21, 2026 8:13:00 AM | G12: Oct 21, 2026 11:30:00 AM | H12: 3134 | I12: 197 | J12: Excluded | L12: 52.23
A13: Household | B13: uuid:14d78f16-d83a-4c01-88ea-9d4fcc0632b2 | C13: aisha.aman | D13: Aisha Aman | E13: 1-14256-23-35644edf-1 | F13: Sep 28, 2026 10:15:00 AM | G13: Sep 28, 2026 11:10:00 PM | H13: 3533 | I13: 775 | J13: Corrected: AM/PM | K13: 55 | L13: 58.88 | M13: -3.88
A14: Household | B14: uuid:36f9774a-2fbc-4a9b-88fd-887cb1fe896b | C14: aisha.aman | D14: Aisha Aman | E14: 1-14235-24-6f85abe4-8 | F14: Oct 12, 2026 11:35:00 AM | G14: Oct 12, 2026 3:38:00 PM | H14: 4089 | I14: 243 | J14: Excluded | L14: 68.15
A15: Household | B15: uuid:3e6e840a-0dfe-4ec3-91c6-ba17f06fc6d0 | C15: aisha.aman | D15: Aisha Aman | E15: 1-14364-23-1b3c4112-4 | F15: Oct 22, 2026 12:43:00 AM | G15: Oct 22, 2026 4:40:00 AM | H15: 449 | I15: 237 | J15: Excluded | L15: 7.48
A16: Household | B16: uuid:5f65c3f9-73fb-46fc-8a90-61ab79594841 | C16: aisha.aman | D16: Aisha Aman | E16: 1-14230-24-4c7d849d-5 | F16: Oct 23, 2026 3:00:00 AM | G16: Oct 23, 2026 3:01:00 PM | H16: 99 | I16: 721 | J16: Corrected: AM/PM | K16: 1 | L16: 1.65 | M16: -0.65
A17: Household | B17: uuid:9ccb7bac-66a8-4022-be12-54653145606f | C17: aisha.aman | D17: Aisha Aman | E17: 1-14285-23-bcd446c7-7 | F17: Oct 7, 2026 8:43:00 AM | G17: Oct 7, 2026 11:55:00 AM | H17: 3369 | I17: 192 | J17: Excluded | L17: 56.15
A18: Household | B18: uuid:c6c95f90-b4c7-4544-9ab3-3224ffb7512b | C18: aisha.aman | D18: Aisha Aman | E18: 1-14256-23-35644edf-1 | F18: Sep 28, 2026 11:15:00 PM | G18: Sep 28, 2026 11:40:00 AM | H18: 1262 | I18: -695 | J18: Corrected: AM/PM | K18: 25 | L18: 21.03 | M18: 3.97
A19: Household | B19: uuid:c9b28ac6-dfe1-4712-bfb3-b3a6302804e5 | C19: aisha.aman | D19: Aisha Aman | E19: 1-14360-24-aa53f107-3 | F19: Oct 2, 2026 11:59:00 AM | G19: Nov 11, 2024 12:46:00 PM | H19: 2638 | I19: -993553 | J19: Corrected: date | K19: 47 | L19: 43.97 | M19: 3.03
A20: Household | B20: uuid:7b12e949-5c9e-4476-82b4-611fe908abea | C20: Asma Bibi | D20: Asma Bibi | E20: 1-39399-23-3db70c9a-14 | F20: Sep 10, 2026 2:16:00 PM | G20: Sep 10, 2026 6:00:00 PM | H20: 2192 | I20: 224 | J20: Excluded | L20: 36.53
A21: Household | B21: uuid:9b4b3d9f-8723-49fd-972e-3a7288903b26 | C21: Asma Bibi | D21: Asma Bibi | E21: 192 | F21: Sep 14, 2026 8:17:00 PM | G21: Sep 15, 2026 11:40:00 AM | H21: 16138 | I21: 923 | J21: Excluded | L21: 268.97
A22: Household | B22: uuid:e309f92c-945f-4cac-a29c-65cc36d05466 | C22: Asma Bibi | D22: Asma Bibi | E22: 1-14271-23-deabd3d9-3 | F22: Oct 28, 2026 8:22:00 AM | G22: Oct 28, 2026 11:25:00 AM | H22: 2610 | I22: 183 | J22: Excluded | L22: 43.5
A23: Household | B23: uuid:87bde6c5-f0be-479e-8f58-c9f9c241d9f9 | C23: Irum Ikram | D23: Irum Ikram | E23: 1-14293-23-117b6e3c-3 | F23: Sep 23, 2026 11:30:00 PM | G23: Sep 23, 2026 12:06:00 PM | H23: 1328 | I23: -684 | J23: Corrected: AM/PM | K23: 36 | L23: 22.13 | M23: 13.87
A24: Household | B24: uuid:2537f168-0867-4182-ab9d-046d9d91b7f4 | C24: Javairia | D24: Javairia | E24: 1378 | F24: Sep 10, 2026 9:56:00 PM | G24: Sep 10, 2026 2:42:00 PM | H24: 2900 | I24: -434 | J24: Excluded | L24: 48.33
A25: Household | B25: uuid:560e0784-8e11-4040-896c-be7293ffb7e4 | C25: Javairia | D25: Javairia | E25: 1-39399-23-09eaa366-8 | F25: Sep 10, 2026 4:02:00 PM | G25: Sep 10, 2026 3:03:00 PM | H25: 1238 | I25: -59 | J25: Excluded | L25: 20.63
A26: Household | B26: uuid:7ef1c0be-6716-4b71-9c31-8d75b21af641 | C26: Javairia | D26: Javairia | E26: 830 | F26: Oct 27, 2026 5:45:00 PM | G26: Oct 27, 2026 4:25:00 PM | H26: 1164 | I26: -80 | J26: Excluded | L26: 19.4
A27: Household | B27: uuid:8a2dffe0-6d59-47e9-9313-9407fb9fa8ef | C27: Javairia | D27: Javairia | E27: 1777 | F27: Sep 10, 2026 10:44:00 PM | G27: Sep 11, 2026 6:03:00 AM | H27: 6161 | I27: 439 | J27: Excluded | L27: 102.68
A28: Household | B28: uuid:8553dea9-d94a-4893-a02e-228bf638c1e7 | C28: Laiba Shams | D28: Laiba Shams | E28: 6 | F28: Oct 21, 2026 1:35:00 AM | G28: Oct 21, 2026 1:42:00 PM | H28: 810 | I28: 727 | J28: Corrected: AM/PM | K28: 7 | L28: 13.5 | M28: -6.5
A29: Household | B29: uuid:86635361-37cc-46ed-b7d5-a185bc7efcd6 | C29: Laiba Shams | D29: Laiba Shams | E29: 1347 | F29: Sep 30, 2026 2:56:00 PM | G29: Sep 21, 2026 3:09:00 PM | H29: 709 | I29: -12947 | J29: Corrected: date | K29: 13 | L29: 11.82 | M29: 1.18
A30: Household | B30: uuid:a79a235f-1a0f-4a06-aa18-124766a36a6f | C30: Laiba Shams | D30: Laiba Shams | E30: 1313 | F30: Sep 29, 2026 12:59:00 PM | G30: Sep 29, 2026 12:56:00 PM | H30: 3235 | I30: -3 | J30: Excluded | L30: 53.92
A31: Household | B31: uuid:aea34beb-203f-46e9-b7de-967acf695f21 | C31: Laiba Shams | D31: Laiba Shams | E31: 1404 | F31: Oct 5, 2026 10:32:00 AM | G31: Oct 4, 2026 11:32:00 AM | H31: 3640 | I31: -1380 | J31: Corrected: date | K31: 60 | L31: 60.67 | M31: -0.67
A32: Household | B32: uuid:cc292060-4d07-470f-b18c-b7794d565872 | C32: Mahnoor | D32: Mahnoor | E32: 2-31381-24-c7e69f8d-12 | F32: Oct 26, 2026 10:42:00 AM | G32: Oct 26, 2026 9:53:00 AM | H32: 2307 | I32: -49 | J32: Excluded | L32: 38.45
A33: Household | B33: uuid:f1fafc54-97f8-47fb-a25f-72e4807f8790 | C33: Mahnoor | D33: Mahnoor | E33: 2-40767-23-e937b6ea-28 | F33: Sep 9, 2026 11:37:00 AM | G33: Sep 9, 2026 3:41:00 PM | H33: 5095 | I33: 244 | J33: Excluded | L33: 84.92
A34: Household | B34: uuid:2e319e61-bd4e-4f74-94e7-7b429509ab7a | C34: Naureen Khan | D34: Naureen Khan | E34: 1-14360-23-9b4588f5-5 | F34: Oct 2, 2026 1:37:00 PM | G34: Oct 2, 2026 1:05:00 PM | H34: 1315 | I34: -32 | J34: Excluded | L34: 21.92
A35: Household | B35: uuid:5d0de21b-0d5f-4698-9666-7488f523722a | C35: Naureen Khan | D35: Naureen Khan | E35: 1-29159-24-02d60b86-1 | F35: Sep 14, 2026 4:35:00 PM | G35: Sep 14, 2026 3:36:00 PM | H35: 2172 | I35: -59 | J35: Excluded | L35: 36.2
A36: Household | B36: uuid:8ca0f900-ce81-42d5-a492-7b883ac9f537 | C36: Naureen Khan | D36: Naureen Khan | E36: 1-39399-24-d2eb4db7-12 | F36: Sep 10, 2026 4:18:00 PM | G36: Sep 10, 2026 7:38:00 PM | H36: 1707 | I36: 200 | J36: Excluded | L36: 28.45
A37: Household | B37: uuid:ab55ac3b-373e-4473-9de1-0a0952aec965 | C37: Naureen Khan | D37: Naureen Khan | E37: 1-14360-23-9b4588f5-5 | F37: Oct 3, 2026 2:16:00 PM | G37: Oct 2, 2026 3:14:00 PM | H37: 1571 | I37: -1382 | J37: Corrected: date | K37: 58 | L37: 26.18 | M37: 31.82
A38: Household | B38: uuid:d8bfc0f6-aa6c-4b8e-a4f3-0463392b3add | C38: Naureen Khan | D38: Naureen Khan | E38: 1-39399-23-dd1fc0f9-23 | F38: Sep 10, 2026 1:44:00 PM | G38: Sep 10, 2026 12:57:00 PM | H38: 1089 | I38: -47 | J38: Excluded | L38: 18.15
A39: Household | B39: uuid:fe00fc6e-84ff-4eec-b1f2-61f0b6cbc67b | C39: Naureen Khan | D39: Naureen Khan | E39: 186 | F39: Oct 23, 2026 1:42:00 PM | G39: Oct 23, 2026 2:11:00 AM | H39: 1775 | I39: -691 | J39: Corrected: AM/PM | K39: 29 | L39: 29.58 | M39: -0.58
A40: Household | B40: uuid:0db290cf-c46a-4a01-b474-9825ffd607a2 | C40: Shafaq Zahra | D40: Shafaq Zahra | E40: 1-14155-23-18da8155-9 | F40: Sep 22, 2026 4:41:00 PM | G40: Sep 22, 2026 3:50:00 PM | H40: 565 | I40: -51 | J40: Excluded | L40: 9.42
...

Sheet Cited_Forms
A1: Cited for | B1: survey | C1: KEY | D1: enumerator_name (as in export) | E1: enumerator (standardised) | F1: girl | G1: starttime1 | H1: Endtime1 | I1: duration (sec) | J1: manual_raw_min | K1: action | L1: manual_used_min | M1: auto_min | N1: gap_min (manual-auto)
A2: Point (i): AM/PM error, Shafaq Zahra HH | B2: Household | C2: uuid:8012730e-e9cc-4d13-b576-e62c671f20a1 | D2: Shafaq Zahra | E2: Shafaq Zahra | F2: 1-37622-24-b055945b-2 | G2: Oct 26, 2026 11:30:00 PM | H2: Oct 26, 2026 12:05:00 PM | I2: 915 | J2: -685 | K2: Corrected: AM/PM | L2: 35 | M2: 15.25 | N2: 19.75
A3: AM/PM error raising Shafaq Zahra Girls mean | B3: Girls | C3: uuid:199ea468-989d-4f8f-85c5-bf5800e6c4fa | D3: Shafaq Zahra | E3: Shafaq Zahra | F3: 1-37622-24-b055945b-2 | G3: Oct 26, 2026 12:25:00 AM | H3: Oct 26, 2026 1:06:00 PM | I3: 1382 | J3: 761 | K3: Corrected: AM/PM | L3: 41 | M3: 23.03 | N3: 17.97
A4: End date 11 Nov 2024, Aisha Aman HH | B4: Household | C4: uuid:c9b28ac6-dfe1-4712-bfb3-b3a6302804e5 | D4: aisha.aman | E4: Aisha Aman | F4: 1-14360-24-aa53f107-3 | G4: Oct 2, 2026 11:59:00 AM | H4: Nov 11, 2024 12:46:00 PM | I4: 2638 | J4: -993553 | K4: Corrected: date | L4: 47 | M4: 43.97 | N4: 3.03
A5: End date (8 Oct) before start date (24 Oct), Naureen Khan Girls | B5: Girls | C5: uuid:7fad4f04-ac02-47d1-b25b-ecab27034177 | D5: Naureen Khan | E5: Naureen Khan | F5: 1-14285-24-8b710a45-7 | G5: Oct 24, 2026 10:55:00 AM | H5: Oct 8, 2026 12:25:00 PM | I5: 1796 | J5: -22950 | K5: Corrected: date | L5: 90 | M5: 29.93 | N5: 60.07
